Workbook

Sheet 说明
A1: 测评录音剧本 · 旅游纠纷录音材料整理项目
A3: 整理日期 | B3: 2026-10-07
A4: 内容 | B4: 8 组 × 3 个剧本，共 24 个虚构情景剧，1055 行台词
A5: 用途 | B5: 照剧本录音，剧本即录音的参考答案；同时提供说话人、话术类别、数字规范写法、热词等标注
A6: 录音量 | B6: 每个剧本 3 种条件各录一遍，共 72 个文件；预计每组每种条件 12—14 分钟，全班合计约 5 小时（见“分组统计”）
A8: 录音条件 | B8: 代码 | C8: 怎么录
A9: 安静 | B9: Q | C9: 安静的教室或会议室；手机平放在说话人中间的桌上，距离约 50 厘米
A10: 嘈杂教室 | B10: N | C10: 课间或几组同时录音的教室；手机位置同上
A11: 口袋或远距离 | B11: F | C11: 手机放在一名演员的外衣口袋里，或放在离说话人 2—3 米外的桌角
A12: 统一设置 | C12: 同一个录音 App，16kHz 单声道 WAV；文件名 = 剧本编号-条件代码.wav，例如 G1-S1-Q.wav
A14: 使用步骤
A15: 1. 在“剧本总览”的“角色分配”栏写清谁演哪个角色。
A16: 2. 照“台词”表录音；“动作与环境提示”一栏不念，只用于表演。
A17: 3. 允许即兴改口，但录完必须对照录音修改“台词”列，以实际说了什么为准；有效字数和预计时长会自动重算。
A18: 4. 每录完一个文件，在“录音计划”登记录音人、日期和实际时长；参考文本校对完成后，再放入共享数据池。
A20: 话术类别 | B20: 含义
A21: 购物安排 | B21: 推荐、安排、推销购物或进店，商品介绍，游客对购物的回应
A22: 费用 | B22: 价格、自费项目、团费、退款、小费等金额相关
A23: 行程变更 | B23: 取消、压缩、调换行程或时间安排变动
A24: 服务态度 | B24: 催促、敷衍、不耐烦，以及对态度的抱怨和道歉
A25: 威胁消费 | B25: 以行程、住宿、服务等为条件含蓄施压要求消费（措辞温和，无辱骂、无人身威胁）
A26: 正常讲解 | B26: 景点介绍、安全提醒、集合通知等正常导游工作
A27: 其他 | B27: 寒暄、问路、附和，以及与上面无关的话
A29: 其他列 | B29: 含义
A30: 数字规范写法 | B30: 台词里的数字一律按口语读法用汉字写；这一列给出规范写法（如 2800元、15:40、YN-0000-3721），供第 4 组做规范化测评
A31: 热词 | B31: 这句里出现的虚构名称、商品行话和地名，供第 5 组整理热词表、统计专名正确率
A32: 有效字数 | B32: 只数汉字、字母和数字，不数标点和空格；与计算 CER 时的口径一致
A33: 标注备注 | B33: 需要提醒的标注难例，例如第 6 组 S3 中游客复述导游原话的 5 句
A35: 格式 | B35: 含义 | D35: 示例
A36: 浅黄色底 | B36: 需要填写的单元格（角色分配、状态、录音人、日期、实际时长、勾选项） | D36: 已录音
A37: 蓝色数字 | B37: 可调整的参数（朗读语速、时长目标等） | D37: 220
A38: 黑色数字 | B38: 本表内的公式结果，不要直接改写 | D38: 4.3
A39: 绿色数字 | B39: 引用其他工作表的公式 | D39: 47
A40: 填写示例：角色分配写“导游：张三；游客甲：李四；游客乙：王五；司机：赵六”；状态和勾选项从下拉列表中选择。
A42: 注意
A43: 1. 全部为虚构的教学情景剧。旅行社、店铺、酒店、人名、号码见“虚构名称”表；如与真实企业重名，请替换后再用。
A44: 2. 内容只涉及购物、费用、行程和服务态度等商业纠纷，不含辱骂、威胁、政治、民族、宗教或地域内容；施压话术均为温和措辞。
A45: 3. 景点介绍只用常识，课前请教师再核对一遍。
A46: 4. 预计时长按朗读语速 220 字/分钟估算，可在“剧本总览”顶部修改；实际时长以录音文件为准。
A47: 5. 录音只用学生本人的声音，录音前签署同意书；剧本和录音中不出现任何真实个人信息。
...

Sheet 剧本总览
A1: 剧本总览（8 组 × 3 个剧本）
A2: 台词行数、有效字数、预计时长由公式根据“台词”表自动计算。蓝色数字可改：朗读语速按实际试读情况调整，时长检查会随之更新。
A3: 朗读语速（字/分钟） | D3: 220
A4: 每个剧本时长下限（分钟） | D4: 3
A5: 每个剧本时长上限（分钟） | D5: 5
A7: 剧本编号 | B7: 组 | C7: 场景 | D7: 标题 | E7: 地点与背景 | F7: 角色 | G7: 本剧本侧重 | H7: 台词行数 | I7: 有效字数 | J7: 预计时长（分钟） | K7: 时长检查 | L7: 角色分配（谁演谁） | M7: 状态
A8: G1-S1 | B8: 1 | C8: 大巴车上推销土特产 | D8: 石林路上推特产 | E8: 上午从昆明开往石林的旅游大巴上，云栖野渡旅行社的周导用车载扩音器介绍行程、推荐鲜花饼和普洱茶，并预告下午返程途中要停暮山特产超市；游客甲和游客乙是结伴报团的老同学。 | F8: 导游、司机、游客甲、游客乙 | G8: 导游扩音器长段讲解与游客“嗯”“好”等极短回应、后排小声议论交替出现，穿插修路颠簸、收费站提示音和三到八秒的车内静默，用来测试降噪后端点检测对短语音和长静音的切分。 | H8: =COUNTIF(台词!$A$5:$A$1059,A8) -> 53 | I8: =SUMIF(台词!$A$5:$A$1059,A8,台词!$J$5:$J$1059) -> 981 | J8: =I8/$D$3 -> 4.4590909 | K8: =IF(AND(J8>=$D$4,J8<=$D$5),"符合","需调整") -> 符合 | M8: 未开始
A9: G1-S2 | B9: 1 | C9: 大巴车上推销土特产 | D9: 能不能不下车 | E9: 午饭后从楚雄开往大理的旅游大巴上，周导讲翡翠手镯怎么挑，并预告要在雾林茶舍停车；游客甲陪母亲游客乙出游，母亲有些晕车，想留在车上休息。 | F9: 导游、司机、游客甲、游客乙 | G9: 游客乙是说话少、声音轻的长辈，回应多为一两个字，再加上隧道回声、扩音器开关声和长达十秒的车内静默，用来测试低能量语音和强背景噪声下的端点检测。 | H9: =COUNTIF(台词!$A$5:$A$1059,A9) -> 49 | I9: =SUMIF(台词!$A$5:$A$1059,A9,台词!$J$5:$J$1059) -> 951 | J9: =I9/$D$3 -> 4.3227273 | K9: =IF(AND(J9>=$D$4,J9<=$D$5),"符合","需调整") -> 符合 | M9: 未开始
A10: G1-S3 | B10: 1 | C10: 大巴车上推销土特产 | D10: 返程拒购与送机 | E10: 行程最后一天上午，旅游大巴从大理返回昆明，周导在车上再次推销雾林茶舍的茶叶和暮山特产超市的土特产，被游客明确拒绝后，转为返程安全提醒和长水机场送机安排；游客甲和游客乙是在团里才认识的两位散客。 | F10: 导游、司机、游客甲、游客乙 | G10: 导游在扩音器远讲和放下扩音器近讲之间切换，夹杂游客干脆简短的拒绝、减速带颠簸、车载导航提示音等非台词声音和多次三到八秒的停顿，用来测试不同信噪比下的降噪效果和端点检测。 | H10: =COUNTIF(台词!$A$5:$A$1059,A10) -> 46 | I10: =SUMIF(台词!$A$5:$A$1059,A10,台词!$J$5:$J$1059) -> 877 | J10: =I10/$D$3 -> 3.9863636 | K10: =IF(AND(J10>=$D$4,J10<=$D$5),"符合","需调整") -> 符合 | M10: 未开始
A11: G2-S1 | B11: 2 | C11: 购物店“包厢式”推销 | D11: 玉石馆的小房间 | E11: 丽江青黛玉石馆二楼的贵宾小房间，店员站在房间另一头的展柜后讲解翡翠手镯，三位游客挤坐在门边的沙发上，录音手机在游客甲的外套口袋里。 | F11: 店员、游客甲、游客乙、游客丙 | G11: 店员隔着房间长段快速讲解、报价一路往下降，游客贴着口袋里的手机短促耳语，游客乙试戴时走远又走回，考查远场、口袋遮挡和远近交替下的识别。 | H11: =COUNTIF(台词!$A$5:$A$1059,A11) -> 46 | I11: =SUMIF(台词!$A$5:$A$1059,A11,台词!$J$5:$J$1059) -> 992 | J11: =I11/$D$3 -> 4.5090909 | K11: =IF(AND(J11>=$D$4,J11<=$D$5),"符合","需调整") -> 符合 | M11: 未开始
A12: G2-S2 | B12: 2 | C12: 购物店“包厢式”推销 | D12: 竹溪茶仓品鉴室 | E12: 大理竹溪茶仓的品鉴室，店员坐在长茶台另一头边泡茶边推荐，马导站在门口帮腔，录音手机放在两位游客跟前的茶台角上。 | F12: 店员、导游、游客甲、游客乙 | G12: 手机在茶台角，店员隔着长茶台边泡边讲、不时转身取茶，导游在门口远处插话，两位游客在手机旁短句耳语，考查不同距离和朝向下的识别。 | H12: =COUNTIF(台词!$A$5:$A$1059,A12) -> 42 | I12: =SUMIF(台词!$A$5:$A$1059,A12,台词!$J$5:$J$1059) -> 947 | J12: =I12/$D$3 -> 4.3045455 | K12: =IF(AND(J12>=$D$4,J12<=$D$5),"符合","需调整") -> 符合 | M12: 未开始
A13: G2-S3 | B13: 2 | C13: 购物店“包厢式”推销 | D13: 手工坊里透口气 | E13: 昆明晓月银坊后面的手工坊，店员在工作台前演示银壶和银饰，经理在屋里来回走动宣传今天特价，屋里人多有点闷，录音手机在游客乙的裤兜里。 | F13: 店员、经理、游客甲、游客乙 | G13: 店员在远处工作台边敲边讲，经理边走边说、忽远忽近，母女俩贴着裤兜里的手机耳语，最后边走边说出门，考查口袋录音、移动声源和背景敲击声下的识别。 | H13: =COUNTIF(台词!$A$5:$A$1059,A13) -> 43 | I13: =SUMIF(台词!$A$5:$A$1059,A13,台词!$J$5:$J$1059) -> 951 | J13: =I13/$D$3 -> 4.3227273 | K13: =IF(AND(J13>=$D$4,J13<=$D$5),"符合","需调整") -> 符合 | M13: 未开始
A14: G3-S1 | B14: 3 | C14: 擅自变更行程 | D14: 游船改去体验中心 | E14: 行程第二天早上八点，大理澄溪假日酒店大堂，青岫远途旅行社的李导召集游客，宣布原定上午的洱海游船取消、改去一个“体验中心”，游客们七嘴八舌地质疑，有人翻出行程单逐条对照。 | F14: 导游、游客甲、游客乙、游客丙、游客丁 | G14: 导游先连续宣布一大段，随后四名游客短句抢话、打断、附和，多处标注重叠和几个人同时说；游客甲、游客乙是结伴出游的两位退休老同事，观点一致、常重复对方的话，宜由声线相近的同学扮演，用来测试说话人分离对快速换人和相似声音的区分。 | H14: =COUNTIF(台词!$A$5:$A$1059,A14) -> 56 | I14: =SUMIF(台词!$A$5:$A$1059,A14,台词!$J$5:$J$1059) -> 925 | J14: =I14/$D$3 -> 4.2045455 | K14: =IF(AND(J14>=$D$4,J14<=$D$5),"符合","需调整") -> 符合 | M14: 未开始
A15: G3-S2 | B15: 3 | C15: 擅自变更行程 | D15: 三小时变一小时 | E15: 行程第三天上午十点，青岫远途旅行社的团刚从城门走进大理古城，李导在城门边的空地上把合同约定的三小时游览压缩成一小时，游客拿出合同要求按约定来，李导打电话给张经理并开了外放。 | F15: 导游、游客甲、游客乙、游客丙、经理 | G15: 现场四人轮流抢话，与电话外放里的经理交替出现，经理有一长段连续讲话，游客还凑近手机插话；游客甲、游客乙是结伴报团的两个年轻同事，观点一致、说话方式几乎一样，宜由声线相近的两位同学扮演，用来测试说话人分离对电话声道、相似声音和插话的区分。 | H15: =COUNTIF(台词!$A$5:$A$1059,A15) -> 51 | I15: =SUMIF(台词!$A$5:$A$1059,A15,台词!$J$5:$J$1059) -> 856 | J15: =I15/$D$3 -> 3.8909091 | K15: =IF(AND(J15>=$D$4,J15<=$D$5),"符合","需调整") -> 符合 | M15: 未开始
A16: G3-S3 | B16: 3 | C16: 擅自变更行程 | D16: 酒店换成远山客栈 | E16: 行程第一天晚上九点多，旅游车停在离大理古城较远的远山客栈门口，游客发现合同上的澄溪假日酒店被换掉，大理和丽江的游览顺序也被调换，游客代表与李导和随后赶来的张经理当面协商。 | F16: 导游、经理、游客甲、游客乙、游客丙 | G16: 导游、经理、游客代表三方轮流交涉，游客甲、游客乙是一对说话腔调相近的姐妹，常抢着接话、同时附和；游客代表有一段很长的连续陈述，导游最后念一遍协议，用来测试说话人分离在多方协商、长段与短句交替时的稳定性。 | H16: =COUNTIF(台词!$A$5:$A$1059,A16) -> 56 | I16: =SUMIF(台词!$A$5:$A$1059,A16,台词!$J$5:$J$1059) -> 992 | J16: =I16/$D$3 -> 4.5090909 | K16: =IF(AND(J16>=$D$4,J16<=$D$5),"符合","需调整") -> 符合 | M16: 未开始
A17: G4-S1 | B17: 4 | C17: 自费项目费用纠纷 | D17: 《云上花间》含不含 | E17: 丽江一家酒店的大堂，行程第三天晚饭后，导游通知晚上的自费演出，游客拿出合同和导游核对条款与价格。 | F17: 导游、游客甲、游客乙、经理 | G17: 演出单价、团费、定金、尾款、差价、退款、人数、排数、房间号、时间日期和合同编号密集出现，同一金额与编号换用多种口语读法，并穿插“一分没少”“十分抱歉”等非数字用法，练习数字识别与规范化。 | H17: =COUNTIF(台词!$A$5:$A$1059,A17) -> 47 | I17: =SUMIF(台词!$A$5:$A$1059,A17,台词!$J$5:$J$1059) -> 993 | J17: =I17/$D$3 -> 4.5136364 | K17: =IF(AND(J17>=$D$4,J17<=$D$5),"符合","需调整") -> 符合 | M17: 未开始
A18: G4-S2 | B18: 4 | C18: 自费项目费用纠纷 | D18: 没坐的钱怎么退 | E18: 大理附近一处湖边景区的出口停车场，下午四点多，部分游客没坐望湖索道或环湖电瓶车，大家围着导游算退款。 | F18: 导游、游客甲、游客乙、游客丙 | G18: 团队价与门市价、人数乘单价、多笔相加、算重后重算、百分比手续费、现金点数和时间调整，集中练习口算场景中金额与人数的识别与规范化。 | H18: =COUNTIF(台词!$A$5:$A$1059,A18) -> 44 | I18: =SUMIF(台词!$A$5:$A$1059,A18,台词!$J$5:$J$1059) -> 981 | J18: =I18/$D$3 -> 4.4590909 | K18: =IF(AND(J18>=$D$4,J18<=$D$5),"符合","需调整") -> 符合 | M18: 未开始
A19: G4-S3 | B19: 4 | C19: 自费项目费用纠纷 | D19: 返程车上对账单 | E19: 行程最后一天下午，从石林返回昆明的大巴上，导游逐项核对一对夫妻的自费账单，游客记下各类号码准备咨询。 | F19: 导游、游客甲、游客乙、司机 | G19: 自费单价、合计、预交、九折、带小数的金额、日期、时间、里程，以及导游证号、旅行社电话、合同编号、订单号和热线号码的多种读法（含“幺”“四个零”“两个六两个八”），并夹有“一五一十”“一分不少”等不应转成阿拉伯数字的说法，集中练习号码与金额的规范化。 | H19: =COUNTIF(台词!$A$5:$A$1059,A19) -> 45 | I19: =SUMIF(台词!$A$5:$A$1059,A19,台词!$J$5:$J$1059) -> 929 | J19: =I19/$D$3 -> 4.2227273 | K19: =IF(AND(J19>=$D$4,J19<=$D$5),"符合","需调整") -> 符合 | M19: 未开始
... A31: G8-S3 | B31: 8 | C31: 正常讲解（对照组） | D31: 古城漫步洱海骑行 | E31: 大理，因为下午可能下雨，星野云途旅行社的何导征得游客同意后改为上午洱海边骑行、下午步行游览大理古城，租车点店员协助说明，全程没有任何纠纷。 | F31: 导游、店员、游客甲、游客乙、游客丙 | G31: 对照组剧本：集中出现“时间调整”“押金”“自费”“加钱”“自由购物时间”“包含在团费里”等容易触发误报的正常说法，配合骑行安全的三句连续长讲解，用于时间戳对齐、证据片段导出和误报率统计。 | H31: =COUNTIF(台词!$A$5:$A$1059,A31) -> 35 | I31: =SUMIF(台词!$A$5:$A$1059,A31,台词!$J$5:$J$1059) -> 994 | J31: =I31/$D$3 -> 4.5181818 | K31: =IF(AND(J31>=$D$4,J31<=$D$5),"符合","需调整") -> 符合 | M31: 未开始
A32: 合计 | H32: =SUM(H8:H31) -> 1055 | I32: =SUM(I8:I31) -> 22853 | J32: =SUM(J8:J31) -> 103.87727 | K32: =COUNTIF(K8:K31,"符合")&" / "&COUNTA(A8:A31)&" 个符合" -> 24 / 24 个符合

Sheet 台词
A1: 全部台词（录音参考文本）
A2: 每句一行。“动作与环境提示”一栏不念，只用于表演。允许即兴改口，但录完必须对照录音修改“台词”列，以实际说了什么为准；修改后有效字数和预计时长会自动重算。可用表头的筛选按钮按剧本、组或话术类别筛选。
A4: 剧本编号 | B4: 组 | C4: 行号 | D4: 说话人 | E4: 台词（参考文本） | F4: 动作与环境提示（不念） | G4: 话术类别 | H4: 数字规范写法 | I4: 热词 | J4: 有效字数 | K4: 标注备注
A5: G1-S1 | B5: 1 | C5: 1 | D5: 导游 | E5: 喂，喂？后面的朋友听得到吗？听得到的举个手。 | F5: （用车载扩音器）（扩音器先尖啸一声） | G5: 其他 | J5: =LEN(E5)-SUMPRODUCT(LEN(E5)-LEN(SUBSTITUTE(E5,{"，","。","？","！","、","…","；","：","《","》"," ","“","”","—","（","）","·"},""))) -> 18
A6: G1-S1 | B6: 1 | C6: 2 | D6: 游客甲 | E6: 听得到！ | F6: （坐在后排，提高声音） | G6: 其他 | J6: =LEN(E6)-SUMPRODUCT(LEN(E6)-LEN(SUBSTITUTE(E6,{"，","。","？","！","、","…","；","：","《","》"," ","“","”","—","（","）","·"},""))) -> 3
A7: G1-S1 | B7: 1 | C7: 3 | D7: 导游 | E7: 好，那我先简单介绍一下。我是云栖野渡旅行社的导游，我姓周，大家叫我周导就行。给我们开车的是司机师傅，开了二十多年车了，大家放心。 | F7: （用车载扩音器） | G7: 正常讲解 | H7: 20多年 | I7: 云栖野渡旅行社；周导 | J7: =LEN(E7)-SUMPRODUCT(LEN(E7)-LEN(SUBSTITUTE(E7,{"，","。","？","！","、","…","；","：","《","》"," ","“","”","—","（","）","·"},""))) -> 56
A8: G1-S1 | B8: 1 | C8: 4 | D8: 司机 | E8: 大家好。 | F8: （在驾驶座，未用扩音器，声音较远） | G8: 其他 | J8: =LEN(E8)-SUMPRODUCT(LEN(E8)-LEN(SUBSTITUTE(E8,{"，","。","？","！","、","…","；","：","《","》"," ","“","”","—","（","）","·"},""))) -> 3
A9: G1-S1 | B9: 1 | C9: 5 | D9: 游客乙 | E9: 师傅好。 | F9: （与上一句部分重叠） | G9: 其他 | J9: =LEN(E9)-SUMPRODUCT(LEN(E9)-LEN(SUBSTITUTE(E9,{"，","。","？","！","、","…","；","：","《","》"," ","“","”","—","（","）","·"},""))) -> 3
A10: G1-S1 | B10: 1 | C10: 6 | D10: 导游 | E10: 我们现在已经出了昆明，往石林方向开，走高速大概还要一个多小时。路上大家把安全带系好，哪里不舒服随时跟我说。 | F10: （用车载扩音器） | G10: 正常讲解 | H10: 1个多小时 | I10: 昆明；石林 | J10: =LEN(E10)-SUMPRODUCT(LEN(E10)-LEN(SUBSTITUTE(E10,{"，","。","？","！","、","…","；","：","《","》"," ","“","”","—","（","）","·"},""))) -> 48
A11: G1-S1 | B11: 1 | C11: 7 | D11: 游客甲 | E11: 好。 | G11: 其他 | J11: =LEN(E11)-SUMPRODUCT(LEN(E11)-LEN(SUBSTITUTE(E11,{"，","。","？","！","、","…","；","：","《","》"," ","“","”","—","（","）","·"},""))) -> 1
A12: G1-S1 | B12: 1 | C12: 8 | D12: 导游 | E12: 石林呢，是比较典型的喀斯特地貌。就是说，石灰岩经过很长时间的溶蚀，变成一根一根的石柱子，远远看过去像一片树林，所以叫石林。 | F12: （用车载扩音器） | G12: 正常讲解 | I12: 石林 | J12: =LEN(E12)-SUMPRODUCT(LEN(E12)-LEN(SUBSTITUTE(E12,{"，","。","？","！","、","…","；","：","《","》"," ","“","”","—","（","）","·"},""))) -> 54
A13: G1-S1 | B13: 1 | C13: 9 | D13: 导游 | E13: 里面台阶多，路也长，今天穿高跟鞋的朋友，嗯，那个，可能会有点辛苦。大家带好水和帽子。 | F13: （用车载扩音器） | G13: 正常讲解 | J13: =LEN(E13)-SUMPRODUCT(LEN(E13)-LEN(SUBSTITUTE(E13,{"，","。","？","！","、","…","；","：","《","》"," ","“","”","—","（","）","·"},""))) -> 35
A14: G1-S1 | B14: 1 | C14: 10 | D14: 游客乙 | E14: 还好我穿的是运动鞋。 | F14: （游客在后排小声说） | G14: 其他 | J14: =LEN(E14)-SUMPRODUCT(LEN(E14)-LEN(SUBSTITUTE(E14,{"，","。","？","！","、","…","；","：","《","》"," ","“","”","—","（","）","·"},""))) -> 9
A15: G1-S1 | B15: 1 | C15: 11 | D15: 游客甲 | E15: 嗯。 | F15: （小声） | G15: 其他 | J15: =LEN(E15)-SUMPRODUCT(LEN(E15)-LEN(SUBSTITUTE(E15,{"，","。","？","！","、","…","；","：","《","》"," ","“","”","—","（","）","·"},""))) -> 1
A16: G1-S1 | B16: 1 | C16: 12 | D16: 导游 | E16: 好，趁着路上还有点时间，跟大家聊聊这边的特产。来昆明玩，有两样东西大家多半都听说过，一个是鲜花饼，一个是普洱茶。 | F16: （过了一会儿）（车内安静约五秒，只有发动机声）（用车载扩音器） | G16: 购物安排 | H16: 2样 | I16: 昆明；鲜花饼；普洱茶 | J16: =LEN(E16)-SUMPRODUCT(LEN(E16)-LEN(SUBSTITUTE(E16,{"，","。","？","！","、","…","；","：","《","》"," ","“","”","—","（","）","·"},""))) -> 49
A17: G1-S1 | B17: 1 | C17: 13 | D17: 导游 | E17: 鲜花饼就是用食用玫瑰做馅儿的酥饼，皮是酥的，里面甜甜的，有一股花香，老人小孩都爱吃。 | F17: （用车载扩音器） | G17: 购物安排 | I17: 鲜花饼；食用玫瑰 | J17: =LEN(E17)-SUMPRODUCT(LEN(E17)-LEN(SUBSTITUTE(E17,{"，","。","？","！","、","…","；","：","《","》"," ","“","”","—","（","）","·"},""))) -> 37
A18: G1-S1 | B18: 1 | C18: 14 | D18: 游客甲 | E18: 这个我知道，我同事上回带过一盒，挺好吃的。 | G18: 购物安排 | H18: 1盒 | J18: =LEN(E18)-SUMPRODUCT(LEN(E18)-LEN(SUBSTITUTE(E18,{"，","。","？","！","、","…","；","：","《","》"," ","“","”","—","（","）","·"},""))) -> 18
A19: G1-S1 | B19: 1 | C19: 15 | D19: 导游 | E19: 对对对。普洱茶呢，分生茶和熟茶，生茶味道清一点，熟茶颜色深一点，喝起来醇一些。一般压成茶饼，常见的一饼是三百五十七克。 | F19: （用车载扩音器） | G19: 购物安排 | H19: 1饼；357克 | I19: 普洱茶；生茶；熟茶；茶饼 | J19: =LEN(E19)-SUMPRODUCT(LEN(E19)-LEN(SUBSTITUTE(E19,{"，","。","？","！","、","…","；","：","《","》"," ","“","”","—","（","）","·"},""))) -> 51
A20: G1-S1 | B20: 1 | C20: 16 | D20: 司机 | E20: 前面这段在修路，有点颠，大家坐稳啊。 | F20: （车辆颠簸） | G20: 正常讲解 | J20: =LEN(E20)-SUMPRODUCT(LEN(E20)-LEN(SUBSTITUTE(E20,{"，","。","？","！","、","…","；","：","《","》"," ","“","”","—","（","）","·"},""))) -> 15
A21: G1-S1 | B21: 1 | C21: 17 | D21: 游客乙 | E21: 哎哟。 | F21: （车辆颠簸时短促出声） | G21: 其他 | J21: =LEN(E21)-SUMPRODUCT(LEN(E21)-LEN(SUBSTITUTE(E21,{"，","。","？","！","、","…","；","：","《","》"," ","“","”","—","（","）","·"},""))) -> 2
A22: G1-S1 | B22: 1 | C22: 18 | D22: 导游 | E22: 没事吧大家？好。下午从石林出来，回昆明的路上，我们会在暮山特产超市停四十分钟。 | F22: （停顿约三秒）（用车载扩音器） | G22: 购物安排 | H22: 40分钟 | I22: 石林；昆明；暮山特产超市 | J22: =LEN(E22)-SUMPRODUCT(LEN(E22)-LEN(SUBSTITUTE(E22,{"，","。","？","！","、","…","；","：","《","》"," ","“","”","—","（","）","·"},""))) -> 34
A23: G1-S1 | B23: 1 | C23: 19 | D23: 导游 | E23: 里面鲜花饼、普洱茶、火腿、小粒咖啡都有。鲜花饼十个一盒，五十八块，买两盒送一个手提袋，坐飞机拎着也方便。 | F23: （用车载扩音器） | G23: 费用 | H23: 10个/盒；58元；2盒；1个 | I23: 鲜花饼；普洱茶；火腿；小粒咖啡 | J23: =LEN(E23)-SUMPRODUCT(LEN(E23)-LEN(SUBSTITUTE(E23,{"，","。","？","！","、","…","；","：","《","》"," ","“","”","—","（","）","·"},""))) -> 44
A24: G1-S1 | B24: 1 | C24: 20 | D24: 游客甲 | E24: 周导，那边能帮忙寄快递吗？我想给家里寄几盒。 | G24: 购物安排 | I24: 周导 | J24: =LEN(E24)-SUMPRODUCT(LEN(E24)-LEN(SUBSTITUTE(E24,{"，","。","？","！","、","…","；","：","《","》"," ","“","”","—","（","）","·"},""))) -> 19
A25: G1-S1 | B25: 1 | C25: 21 | D25: 导游 | E25: 可以的，超市里就能打包寄，邮费另外算。 | F25: （用车载扩音器） | G25: 购物安排 | J25: =LEN(E25)-SUMPRODUCT(LEN(E25)-LEN(SUBSTITUTE(E25,{"，","。","？","！","、","…","；","：","《","》"," ","“","”","—","（","）","·"},""))) -> 16
A26: G1-S1 | B26: 1 | C26: 22 | D26: 游客甲 | E26: 那行，到时候我去看看。 | G26: 购物安排 | J26: =LEN(E26)-SUMPRODUCT(LEN(E26)-LEN(SUBSTITUTE(E26,{"，","。","？","！","、","…","；","：","《","》"," ","“","”","—","（","）","·"},""))) -> 9
A27: G1-S1 | B27: 1 | C27: 23 | D27: 游客乙 | E27: 这种店里的东西肯定比外面贵，你别一下子买太多。 | F27: （游客在后排小声说） | G27: 购物安排 | J27: =LEN(E27)-SUMPRODUCT(LEN(E27)-LEN(SUBSTITUTE(E27,{"，","。","？","！","、","…","；","：","《","》"," ","“","”","—","（","）","·"},""))) -> 21
A28: G1-S1 | B28: 1 | C28: 24 | D28: 游客甲 | E28: 知道了。 | F28: （小声） | G28: 其他 | J28: =LEN(E28)-SUMPRODUCT(LEN(E28)-LEN(SUBSTITUTE(E28,{"，","。","？","！","、","…","；","：","《","》"," ","“","”","—","（","）","·"},""))) -> 3
A29: G1-S1 | B29: 1 | C29: 25 | D29: 导游 | E29: 后排那位朋友，您平时喝不喝普洱？ | F29: （用车载扩音器） | G29: 购物安排 | I29: 普洱 | J29: =LEN(E29)-SUMPRODUCT(LEN(E29)-LEN(SUBSTITUTE(E29,{"，","。","？","！","、","…","；","：","《","》"," ","“","”","—","（","）","·"},""))) -> 14
A30: G1-S1 | B30: 1 | C30: 26 | D30: 游客乙 | E30: 喝啊，家里还有好几饼没拆呢。 | G30: 购物安排 | J30: =LEN(E30)-SUMPRODUCT(LEN(E30)-LEN(SUBSTITUTE(E30,{"，","。","？","！","、","…","；","：","《","》"," ","“","”","—","（","）","·"},""))) -> 12
A31: G1-S1 | B31: 1 | C31: 27 | D31: 导游 | E31: 那正好可以对比一下嘛，我们那边的熟茶都是…… | F31: （用车载扩音器）（说到一半被打断） | G31: 购物安排 | I31: 熟茶 | J31: =LEN(E31)-SUMPRODUCT(LEN(E31)-LEN(SUBSTITUTE(E31,{"，","。","？","！","、","…","；","：","《","》"," ","“","”","—","（","）","·"},""))) -> 19
A32: G1-S1 | B32: 1 | C32: 28 | D32: 游客乙 | E32: 不用不用，我这次不买茶，真的。 | F32: （与上一句部分重叠） | G32: 购物安排 | J32: =LEN(E32)-SUMPRODUCT(LEN(E32)-LEN(SUBSTITUTE(E32,{"，","。","？","！","、","…","；","：","《","》"," ","“","”","—","（","）","·"},""))) -> 12
A33: G1-S1 | B33: 1 | C33: 29 | D33: 导游 | E33: 好，好，不买也没关系，进去看看、上个洗手间也行。 | F33: （停顿约两秒） | G33: 购物安排 | J33: =LEN(E33)-SUMPRODUCT(LEN(E33)-LEN(SUBSTITUTE(E33,{"，","。","？","！","、","…","；","：","《","》"," ","“","”","—","（","）","·"},""))) -> 19
A34: G1-S1 | B34: 1 | C34: 30 | D34: 游客乙 | E34: 嗯。 | G34: 其他 | J34: =LEN(E34)-SUMPRODUCT(LEN(E34)-LEN(SUBSTITUTE(E34,{"，","。","？","！","、","…","；","：","《","》"," ","“","”","—","（","）","·"},""))) -> 1
A35: G1-S1 | B35: 1 | C35: 31 | D35: 司机 | E35: 周导，前面收费站了。 | F35: （车辆减速） | G35: 其他 | I35: 周导 | J35: =LEN(E35)-SUMPRODUCT(LEN(E35)-LEN(SUBSTITUTE(E35,{"，","。","？","！","、","…","；","：","《","》"," ","“","”","—","（","）","·"},""))) -> 8
A36: G1-S1 | B36: 1 | C36: 32 | D36: 导游 | E36: 要得。 | F36: （放下扩音器，对司机说） | G36: 其他 | J36: =LEN(E36)-SUMPRODUCT(LEN(E36)-LEN(SUBSTITUTE(E36,{"，","。","？","！","、","…","；","：","《","》"," ","“","”","—","（","）","·"},""))) -> 2
A37: G1-S1 | B37: 1 | C37: 33 | D37: 游客甲 | E37: 周导，停超市会不会占石林的时间啊？ | F37: （车内安静约五秒，过收费站时有提示音）（提高声音） | G37: 行程变更 | I37: 周导；石林 | J37: =LEN(E37)-SUMPRODUCT(LEN(E37)-LEN(SUBSTITUTE(E37,{"，","。","？","！","、","…","；","：","《","》"," ","“","”","—","（","）","·"},""))) -> 15
A38: G1-S1 | B38: 1 | C38: 34 | D38: 导游 | E38: 不会不会，石林给大家留足两个半小时，超市是回来顺路停的，不影响。 | F38: （用车载扩音器） | G38: 行程变更 | H38: 2.5小时 | I38: 石林 | J38: =LEN(E38)-SUMPRODUCT(LEN(E38)-LEN(SUBSTITUTE(E38,{"，","。","？","！","、","…","；","：","《","》"," ","“","”","—","（","）","·"},""))) -> 28
A39: G1-S1 | B39: 1 | C39: 35 | D39: 游客乙 | E39: 那还行。 | G39: 其他 | J39: =LEN(E39)-SUMPRODUCT(LEN(E39)-LEN(SUBSTITUTE(E39,{"，","。","？","！","、","…","；","：","《","》"," ","“","”","—","（","）","·"},""))) -> 3
A40: G1-S1 | B40: 1 | C40: 36 | D40: 游客乙 | E40: 不过鲜花饼外面也就三四十块一盒吧？ | F40: （停顿约两秒） | G40: 费用 | H40: 30-40元/盒 | I40: 鲜花饼 | J40: =LEN(E40)-SUMPRODUCT(LEN(E40)-LEN(SUBSTITUTE(E40,{"，","。","？","！","、","…","；","：","《","》"," ","“","”","—","（","）","·"},""))) -> 16
A41: G1-S1 | B41: 1 | C41: 37 | D41: 导游 | E41: 那不一样，外面有的是机器做的，个头小，我们那边是当天现烤的。当然了，买不买都看大家自己。 | F41: （用车载扩音器） | G41: 购物安排 | J41: =LEN(E41)-SUMPRODUCT(LEN(E41)-LEN(SUBSTITUTE(E41,{"，","。","？","！","、","…","；","：","《","》"," ","“","”","—","（","）","·"},""))) -> 38
...

Sheet 分组统计
A1: 分组统计
A2: 检查每组每种录音条件是否有 10 分钟以上、三种条件合计是否在 30—45 分钟，以及全班合计是否在 4—6 小时。蓝色数字为可调整的目标值。
A3: 每种条件最少（分钟） | B3: 10
A4: 三种条件合计下限（分钟） | B4: 30
A5: 三种条件合计上限（分钟） | B5: 45
A6: 录音条件数 | B6: 3
A7: 全班合计下限（小时） | B7: 4
A8: 全班合计上限（小时） | B8: 6
A10: 组 | B10: 场景 | C10: 专项 | D10: 剧本数 | E10: 台词行数 | F10: 有效字数 | G10: 每种条件预计时长（分钟） | H10: 每种条件是否够 10 分钟 | I10: 三种条件合计（分钟） | J10: 合计是否在 30—45 分钟
A11: 1 | B11: 大巴车上推销土特产 | C11: 降噪与语音端点检测 | D11: =COUNTIF(剧本总览!$B$8:$B$31,A11) -> 3 | E11: =SUMIF(剧本总览!$B$8:$B$31,A11,剧本总览!$H$8:$H$31) -> 148 | F11: =SUMIF(剧本总览!$B$8:$B$31,A11,剧本总览!$I$8:$I$31) -> 2809 | G11: =SUMIF(剧本总览!$B$8:$B$31,A11,剧本总览!$J$8:$J$31) -> 12.768182 | H11: =IF(G11>=$B$3,"够","不够") -> 够 | I11: =G11*$B$6 -> 38.304545 | J11: =IF(AND(I11>=$B$4,I11<=$B$5),"符合","需调整") -> 符合
A12: 2 | B12: 购物店“包厢式”推销 | C12: 远距离、手机放口袋时的识别 | D12: =COUNTIF(剧本总览!$B$8:$B$31,A12) -> 3 | E12: =SUMIF(剧本总览!$B$8:$B$31,A12,剧本总览!$H$8:$H$31) -> 131 | F12: =SUMIF(剧本总览!$B$8:$B$31,A12,剧本总览!$I$8:$I$31) -> 2890 | G12: =SUMIF(剧本总览!$B$8:$B$31,A12,剧本总览!$J$8:$J$31) -> 13.136364 | H12: =IF(G12>=$B$3,"够","不够") -> 够 | I12: =G12*$B$6 -> 39.409091 | J12: =IF(AND(I12>=$B$4,I12<=$B$5),"符合","需调整") -> 符合
A13: 3 | B13: 擅自变更行程 | C13: 说话人分离 | D13: =COUNTIF(剧本总览!$B$8:$B$31,A13) -> 3 | E13: =SUMIF(剧本总览!$B$8:$B$31,A13,剧本总览!$H$8:$H$31) -> 163 | F13: =SUMIF(剧本总览!$B$8:$B$31,A13,剧本总览!$I$8:$I$31) -> 2773 | G13: =SUMIF(剧本总览!$B$8:$B$31,A13,剧本总览!$J$8:$J$31) -> 12.604545 | H13: =IF(G13>=$B$3,"够","不够") -> 够 | I13: =G13*$B$6 -> 37.813636 | J13: =IF(AND(I13>=$B$4,I13<=$B$5),"符合","需调整") -> 符合
A14: 4 | B14: 自费项目费用纠纷 | C14: 数字、证号、金额规范化 | D14: =COUNTIF(剧本总览!$B$8:$B$31,A14) -> 3 | E14: =SUMIF(剧本总览!$B$8:$B$31,A14,剧本总览!$H$8:$H$31) -> 136 | F14: =SUMIF(剧本总览!$B$8:$B$31,A14,剧本总览!$I$8:$I$31) -> 2903 | G14: =SUMIF(剧本总览!$B$8:$B$31,A14,剧本总览!$J$8:$J$31) -> 13.195455 | H14: =IF(G14>=$B$3,"够","不够") -> 够 | I14: =G14*$B$6 -> 39.586364 | J14: =IF(AND(I14>=$B$4,I14<=$B$5),"符合","需调整") -> 符合
A15: 5 | B15: 兜售物品、索要小费 | C15: 热词 | D15: =COUNTIF(剧本总览!$B$8:$B$31,A15) -> 3 | E15: =SUMIF(剧本总览!$B$8:$B$31,A15,剧本总览!$H$8:$H$31) -> 119 | F15: =SUMIF(剧本总览!$B$8:$B$31,A15,剧本总览!$I$8:$I$31) -> 2851 | G15: =SUMIF(剧本总览!$B$8:$B$31,A15,剧本总览!$J$8:$J$31) -> 12.959091 | H15: =IF(G15>=$B$3,"够","不够") -> 够 | I15: =G15*$B$6 -> 38.877273 | J15: =IF(AND(I15>=$B$4,I15<=$B$5),"符合","需调整") -> 符合
A16: 6 | B16: 言语施压、强迫消费（措辞温和） | C16: TensorFlow 话术分类（模型 A） | D16: =COUNTIF(剧本总览!$B$8:$B$31,A16) -> 3 | E16: =SUMIF(剧本总览!$B$8:$B$31,A16,剧本总览!$H$8:$H$31) -> 125 | F16: =SUMIF(剧本总览!$B$8:$B$31,A16,剧本总览!$I$8:$I$31) -> 2964 | G16: =SUMIF(剧本总览!$B$8:$B$31,A16,剧本总览!$J$8:$J$31) -> 13.472727 | H16: =IF(G16>=$B$3,"够","不够") -> 够 | I16: =G16*$B$6 -> 40.418182 | J16: =IF(AND(I16>=$B$4,I16<=$B$5),"符合","需调整") -> 符合
A17: 7 | B17: 服务态度纠纷 | C17: TensorFlow 话术分类（模型 B） | D17: =COUNTIF(剧本总览!$B$8:$B$31,A17) -> 3 | E17: =SUMIF(剧本总览!$B$8:$B$31,A17,剧本总览!$H$8:$H$31) -> 124 | F17: =SUMIF(剧本总览!$B$8:$B$31,A17,剧本总览!$I$8:$I$31) -> 2694 | G17: =SUMIF(剧本总览!$B$8:$B$31,A17,剧本总览!$J$8:$J$31) -> 12.245455 | H17: =IF(G17>=$B$3,"够","不够") -> 够 | I17: =G17*$B$6 -> 36.736364 | J17: =IF(AND(I17>=$B$4,I17<=$B$5),"符合","需调整") -> 符合
A18: 8 | B18: 正常讲解（对照组） | C18: 时间戳与证据片段导出、误报率 | D18: =COUNTIF(剧本总览!$B$8:$B$31,A18) -> 3 | E18: =SUMIF(剧本总览!$B$8:$B$31,A18,剧本总览!$H$8:$H$31) -> 109 | F18: =SUMIF(剧本总览!$B$8:$B$31,A18,剧本总览!$I$8:$I$31) -> 2969 | G18: =SUMIF(剧本总览!$B$8:$B$31,A18,剧本总览!$J$8:$J$31) -> 13.495455 | H18: =IF(G18>=$B$3,"够","不够") -> 够 | I18: =G18*$B$6 -> 40.486364 | J18: =IF(AND(I18>=$B$4,I18<=$B$5),"符合","需调整") -> 符合
A19: 全班合计 | D19: =SUM(D11:D18) -> 24 | E19: =SUM(E11:E18) -> 1055 | F19: =SUM(F11:F18) -> 22853 | G19: =SUM(G11:G18) -> 103.87727 | I19: =SUM(I11:I18) -> 311.63182
A20: 全班合计（小时） | I20: =I19/60 -> 5.1938636 | J20: =IF(AND(I20>=$B$7,I20<=$B$8),"符合","需调整") -> 符合
A22: 话术类别分布（台词行数）
A23: 话术类别 | B23: 1 | C23: 2 | D23: 3 | E23: 4 | F23: 5 | G23: 6 | H23: 7 | I23: 8 | J23: 合计
A24: 购物安排 | B24: =COUNTIFS(台词!$B$5:$B$1059,B$23,台词!$G$5:$G$1059,$A24) -> 47 | C24: =COUNTIFS(台词!$B$5:$B$1059,C$23,台词!$G$5:$G$1059,$A24) -> 58 | D24: =COUNTIFS(台词!$B$5:$B$1059,D$23,台词!$G$5:$G$1059,$A24) -> 6 | E24: =COUNTIFS(台词!$B$5:$B$1059,E$23,台词!$G$5:$G$1059,$A24) -> 0 | F24: =COUNTIFS(台词!$B$5:$B$1059,F$23,台词!$G$5:$G$1059,$A24) -> 47 | G24: =COUNTIFS(台词!$B$5:$B$1059,G$23,台词!$G$5:$G$1059,$A24) -> 18 | H24: =COUNTIFS(台词!$B$5:$B$1059,H$23,台词!$G$5:$G$1059,$A24) -> 0 | I24: =COUNTIFS(台词!$B$5:$B$1059,I$23,台词!$G$5:$G$1059,$A24) -> 7 | J24: =SUM(B24:I24) -> 183
A25: 费用 | B25: =COUNTIFS(台词!$B$5:$B$1059,B$23,台词!$G$5:$G$1059,$A25) -> 8 | C25: =COUNTIFS(台词!$B$5:$B$1059,C$23,台词!$G$5:$G$1059,$A25) -> 40 | D25: =COUNTIFS(台词!$B$5:$B$1059,D$23,台词!$G$5:$G$1059,$A25) -> 10 | E25: =COUNTIFS(台词!$B$5:$B$1059,E$23,台词!$G$5:$G$1059,$A25) -> 88 | F25: =COUNTIFS(台词!$B$5:$B$1059,F$23,台词!$G$5:$G$1059,$A25) -> 34 | G25: =COUNTIFS(台词!$B$5:$B$1059,G$23,台词!$G$5:$G$1059,$A25) -> 9 | H25: =COUNTIFS(台词!$B$5:$B$1059,H$23,台词!$G$5:$G$1059,$A25) -> 0 | I25: =COUNTIFS(台词!$B$5:$B$1059,I$23,台词!$G$5:$G$1059,$A25) -> 19 | J25: =SUM(B25:I25) -> 208
A26: 行程变更 | B26: =COUNTIFS(台词!$B$5:$B$1059,B$23,台词!$G$5:$G$1059,$A26) -> 5 | C26: =COUNTIFS(台词!$B$5:$B$1059,C$23,台词!$G$5:$G$1059,$A26) -> 4 | D26: =COUNTIFS(台词!$B$5:$B$1059,D$23,台词!$G$5:$G$1059,$A26) -> 70 | E26: =COUNTIFS(台词!$B$5:$B$1059,E$23,台词!$G$5:$G$1059,$A26) -> 3 | F26: =COUNTIFS(台词!$B$5:$B$1059,F$23,台词!$G$5:$G$1059,$A26) -> 1 | G26: =COUNTIFS(台词!$B$5:$B$1059,G$23,台词!$G$5:$G$1059,$A26) -> 12 | H26: =COUNTIFS(台词!$B$5:$B$1059,H$23,台词!$G$5:$G$1059,$A26) -> 11 | I26: =COUNTIFS(台词!$B$5:$B$1059,I$23,台词!$G$5:$G$1059,$A26) -> 13 | J26: =SUM(B26:I26) -> 119
A27: 服务态度 | B27: =COUNTIFS(台词!$B$5:$B$1059,B$23,台词!$G$5:$G$1059,$A27) -> 7 | C27: =COUNTIFS(台词!$B$5:$B$1059,C$23,台词!$G$5:$G$1059,$A27) -> 1 | D27: =COUNTIFS(台词!$B$5:$B$1059,D$23,台词!$G$5:$G$1059,$A27) -> 18 | E27: =COUNTIFS(台词!$B$5:$B$1059,E$23,台词!$G$5:$G$1059,$A27) -> 7 | F27: =COUNTIFS(台词!$B$5:$B$1059,F$23,台词!$G$5:$G$1059,$A27) -> 6 | G27: =COUNTIFS(台词!$B$5:$B$1059,G$23,台词!$G$5:$G$1059,$A27) -> 18 | H27: =COUNTIFS(台词!$B$5:$B$1059,H$23,台词!$G$5:$G$1059,$A27) -> 53 | I27: =COUNTIFS(台词!$B$5:$B$1059,I$23,台词!$G$5:$G$1059,$A27) -> 0 | J27: =SUM(B27:I27) -> 110
A28: 威胁消费 | B28: =COUNTIFS(台词!$B$5:$B$1059,B$23,台词!$G$5:$G$1059,$A28) -> 1 | C28: =COUNTIFS(台词!$B$5:$B$1059,C$23,台词!$G$5:$G$1059,$A28) -> 1 | D28: =COUNTIFS(台词!$B$5:$B$1059,D$23,台词!$G$5:$G$1059,$A28) -> 1 | E28: =COUNTIFS(台词!$B$5:$B$1059,E$23,台词!$G$5:$G$1059,$A28) -> 1 | F28: =COUNTIFS(台词!$B$5:$B$1059,F$23,台词!$G$5:$G$1059,$A28) -> 2 | G28: =COUNTIFS(台词!$B$5:$B$1059,G$23,台词!$G$5:$G$1059,$A28) -> 35 | H28: =COUNTIFS(台词!$B$5:$B$1059,H$23,台词!$G$5:$G$1059,$A28) -> 0 | I28: =COUNTIFS(台词!$B$5:$B$1059,I$23,台词!$G$5:$G$1059,$A28) -> 0 | J28: =SUM(B28:I28) -> 41
A29: 正常讲解 | B29: =COUNTIFS(台词!$B$5:$B$1059,B$23,台词!$G$5:$G$1059,$A29) -> 28 | C29: =COUNTIFS(台词!$B$5:$B$1059,C$23,台词!$G$5:$G$1059,$A29) -> 1 | D29: =COUNTIFS(台词!$B$5:$B$1059,D$23,台词!$G$5:$G$1059,$A29) -> 7 | E29: =COUNTIFS(台词!$B$5:$B$1059,E$23,台词!$G$5:$G$1059,$A29) -> 10 | F29: =COUNTIFS(台词!$B$5:$B$1059,F$23,台词!$G$5:$G$1059,$A29) -> 13 | G29: =COUNTIFS(台词!$B$5:$B$1059,G$23,台词!$G$5:$G$1059,$A29) -> 14 | H29: =COUNTIFS(台词!$B$5:$B$1059,H$23,台词!$G$5:$G$1059,$A29) -> 33 | I29: =COUNTIFS(台词!$B$5:$B$1059,I$23,台词!$G$5:$G$1059,$A29) -> 49 | J29: =SUM(B29:I29) -> 155
A30: 其他 | B30: =COUNTIFS(台词!$B$5:$B$1059,B$23,台词!$G$5:$G$1059,$A30) -> 52 | C30: =COUNTIFS(台词!$B$5:$B$1059,C$23,台词!$G$5:$G$1059,$A30) -> 26 | D30: =COUNTIFS(台词!$B$5:$B$1059,D$23,台词!$G$5:$G$1059,$A30) -> 51 | E30: =COUNTIFS(台词!$B$5:$B$1059,E$23,台词!$G$5:$G$1059,$A30) -> 27 | F30: =COUNTIFS(台词!$B$5:$B$1059,F$23,台词!$G$5:$G$1059,$A30) -> 16 | G30: =COUNTIFS(台词!$B$5:$B$1059,G$23,台词!$G$5:$G$1059,$A30) -> 19 | H30: =COUNTIFS(台词!$B$5:$B$1059,H$23,台词!$G$5:$G$1059,$A30) -> 27 | I30: =COUNTIFS(台词!$B$5:$B$1059,I$23,台词!$G$5:$G$1059,$A30) -> 21 | J30: =SUM(B30:I30) -> 239
A31: 合计 | B31: =SUM(B24:B30) -> 148 | C31: =SUM(C24:C30) -> 131 | D31: =SUM(D24:D30) -> 163 | E31: =SUM(E24:E30) -> 136 | F31: =SUM(F24:F30) -> 119 | G31: =SUM(G24:G30) -> 125 | H31: =SUM(H24:H30) -> 124 | I31: =SUM(I24:I30) -> 109 | J31: =SUM(J24:J30) -> 1055

Sheet 录音计划
A1: 录音计划（24 个剧本 × 3 种条件 = 72 个录音文件）
A2: 文件名 = 剧本编号-条件代码.wav（Q 安静，N 嘈杂教室，F 口袋或远距离）。统一用同一个录音 App，16kHz 单声道 WAV。录音人、日期、实际时长和两个勾选项为待填写项。
A4: 录音文件名 | B4: 剧本编号 | C4: 组 | D4: 录音条件 | E4: 条件代码 | F4: 怎么录 | G4: 预计时长（分钟） | H4: 录音人 | I4: 录音日期 | J4: 实际时长（分钟） | K4: 参考文本已校对 | L4: 已放入数据池
A5: =B5&"-"&E5&".wav" -> G1-S1-Q.wav | B5: G1-S1 | C5: 1 | D5: 安静 | E5: Q | F5: 安静的教室或会议室；手机平放在说话人中间的桌上，距离约 50 厘米 | G5: =INDEX(剧本总览!$J$8:$J$31,MATCH(B5,剧本总览!$A$8:$A$31,0)) -> 4.4590909 | K5: 否 | L5: 否
A6: =B6&"-"&E6&".wav" -> G1-S1-N.wav | B6: G1-S1 | C6: 1 | D6: 嘈杂教室 | E6: N | F6: 课间或几组同时录音的教室；手机位置同上 | G6: =INDEX(剧本总览!$J$8:$J$31,MATCH(B6,剧本总览!$A$8:$A$31,0)) -> 4.4590909 | K6: 否 | L6: 否
A7: =B7&"-"&E7&".wav" -> G1-S1-F.wav | B7: G1-S1 | C7: 1 | D7: 口袋或远距离 | E7: F | F7: 手机放在一名演员的外衣口袋里，或放在离说话人 2—3 米外的桌角 | G7: =INDEX(剧本总览!$J$8:$J$31,MATCH(B7,剧本总览!$A$8:$A$31,0)) -> 4.4590909 | K7: 否 | L7: 否
A8: =B8&"-"&E8&".wav" -> G1-S2-Q.wav | B8: G1-S2 | C8: 1 | D8: 安静 | E8: Q | F8: 安静的教室或会议室；手机平放在说话人中间的桌上，距离约 50 厘米 | G8: =INDEX(剧本总览!$J$8:$J$31,MATCH(B8,剧本总览!$A$8:$A$31,0)) -> 4.3227273 | K8: 否 | L8: 否
A9: =B9&"-"&E9&".wav" -> G1-S2-N.wav | B9: G1-S2 | C9: 1 | D9: 嘈杂教室 | E9: N | F9: 课间或几组同时录音的教室；手机位置同上 | G9: =INDEX(剧本总览!$J$8:$J$31,MATCH(B9,剧本总览!$A$8:$A$31,0)) -> 4.3227273 | K9: 否 | L9: 否
A10: =B10&"-"&E10&".wav" -> G1-S2-F.wav | B10: G1-S2 | C10: 1 | D10: 口袋或远距离 | E10: F | F10: 手机放在一名演员的外衣口袋里，或放在离说话人 2—3 米外的桌角 | G10: =INDEX(剧本总览!$J$8:$J$31,MATCH(B10,剧本总览!$A$8:$A$31,0)) -> 4.3227273 | K10: 否 | L10: 否
A11: =B11&"-"&E11&".wav" -> G1-S3-Q.wav | B11: G1-S3 | C11: 1 | D11: 安静 | E11: Q | F11: 安静的教室或会议室；手机平放在说话人中间的桌上，距离约 50 厘米 | G11: =INDEX(剧本总览!$J$8:$J$31,MATCH(B11,剧本总览!$A$8:$A$31,0)) -> 3.9863636 | K11: 否 | L11: 否
A12: =B12&"-"&E12&".wav" -> G1-S3-N.wav | B12: G1-S3 | C12: 1 | D12: 嘈杂教室 | E12: N | F12: 课间或几组同时录音的教室；手机位置同上 | G12: =INDEX(剧本总览!$J$8:$J$31,MATCH(B12,剧本总览!$A$8:$A$31,0)) -> 3.9863636 | K12: 否 | L12: 否
A13: =B13&"-"&E13&".wav" -> G1-S3-F.wav | B13: G1-S3 | C13: 1 | D13: 口袋或远距离 | E13: F | F13: 手机放在一名演员的外衣口袋里，或放在离说话人 2—3 米外的桌角 | G13: =INDEX(剧本总览!$J$8:$J$31,MATCH(B13,剧本总览!$A$8:$A$31,0)) -> 3.9863636 | K13: 否 | L13: 否
A14: =B14&"-"&E14&".wav" -> G2-S1-Q.wav | B14: G2-S1 | C14: 2 | D14: 安静 | E14: Q | F14: 安静的教室或会议室；手机平放在说话人中间的桌上，距离约 50 厘米 | G14: =INDEX(剧本总览!$J$8:$J$31,MATCH(B14,剧本总览!$A$8:$A$31,0)) -> 4.5090909 | K14: 否 | L14: 否
A15: =B15&"-"&E15&".wav" -> G2-S1-N.wav | B15: G2-S1 | C15: 2 | D15: 嘈杂教室 | E15: N | F15: 课间或几组同时录音的教室；手机位置同上 | G15: =INDEX(剧本总览!$J$8:$J$31,MATCH(B15,剧本总览!$A$8:$A$31,0)) -> 4.5090909 | K15: 否 | L15: 否
A16: =B16&"-"&E16&".wav" -> G2-S1-F.wav | B16: G2-S1 | C16: 2 | D16: 口袋或远距离 | E16: F | F16: 手机放在一名演员的外衣口袋里，或放在离说话人 2—3 米外的桌角 | G16: =INDEX(剧本总览!$J$8:$J$31,MATCH(B16,剧本总览!$A$8:$A$31,0)) -> 4.5090909 | K16: 否 | L16: 否
... A76: =B76&"-"&E76&".wav" -> G8-S3-F.wav | B76: G8-S3 | C76: 8 | D76: 口袋或远距离 | E76: F | F76: 手机放在一名演员的外衣口袋里，或放在离说话人 2—3 米外的桌角 | G76: =INDEX(剧本总览!$J$8:$J$31,MATCH(B76,剧本总览!$A$8:$A$31,0)) -> 4.5181818 | K76: 否 | L76: 否
A78: 汇总
A79: 项目 | B79: 预计（分钟） | C79: 实际（分钟） | D79: 已完成
A80: 安静 | B80: =SUMIF($D$5:$D$76,"安静",$G$5:$G$76) -> 103.87727 | C80: =SUMIF($D$5:$D$76,A80,$J$5:$J$76) -> 0 | D80: =COUNTIFS($D$5:$D$76,A80,$L$5:$L$76,"是")&" / "&COUNTIF($D$5:$D$76,A80) -> 0 / 24
A81: 嘈杂教室 | B81: =SUMIF($D$5:$D$76,"嘈杂教室",$G$5:$G$76) -> 103.87727 | C81: =SUMIF($D$5:$D$76,A81,$J$5:$J$76) -> 0 | D81: =COUNTIFS($D$5:$D$76,A81,$L$5:$L$76,"是")&" / "&COUNTIF($D$5:$D$76,A81) -> 0 / 24
A82: 口袋或远距离 | B82: =SUMIF($D$5:$D$76,"口袋或远距离",$G$5:$G$76) -> 103.87727 | C82: =SUMIF($D$5:$D$76,A82,$J$5:$J$76) -> 0 | D82: =COUNTIFS($D$5:$D$76,A82,$L$5:$L$76,"是")&" / "&COUNTIF($D$5:$D$76,A82) -> 0 / 24
A83: 合计（分钟） | B83: =SUM(B80:B82) -> 311.63182 | C83: =SUM(C80:C82) -> 0 | D83: =COUNTIF($L$5:$L$76,"是")&" / "&COUNTA($B$5:$B$76) -> 0 / 72
A84: 合计（小时） | B84: =B83/60 -> 5.1938636 | C84: =C83/60 -> 0

Sheet 虚构名称
A1: 虚构名称与号码
A2: 剧本中所有旅行社、店铺、酒店、人名、号码均为虚构。如发现与真实企业或人员重名，请统一替换后再使用。这张表也可直接作为第 5 组热词表的起点。
A4: 类型 | B4: 名称 | C4: 出现的组 | D4: 说明
A5: 旅行社 | B5: 云栖野渡旅行社 | C5: 第 1 组 | D5: 虚构
A6: 旅行社 | B6: 鹿鸣七彩旅行社 | C6: 第 2 组 | D6: 虚构
A7: 旅行社 | B7: 青岫远途旅行社 | C7: 第 3 组 | D7: 虚构
A8: 旅行社 | B8: 拾光滇程旅行社 | C8: 第 4 组 | D8: 虚构
A9: 旅行社 | B9: 雾隐行舟旅行社 | C9: 第 5 组 | D9: 虚构；剧本中故意出现“雾隐晚渡”“雾隐那家”等说错或简称
A10: 旅行社 | B10: 松风晚渡旅行社 | C10: 第 5 组 | D10: 虚构；剧本中故意出现“松风行舟”等说错
A11: 旅行社 | B11: 听澜百川旅行社 | C11: 第 6 组 | D11: 虚构
A12: 旅行社 | B12: 半山观澜旅行社 | C12: 第 7 组 | D12: 虚构
A13: 旅行社 | B13: 星野云途旅行社 | C13: 第 8 组 | D13: 虚构
A14: 店铺 | B14: 暮山特产超市 | C14: 第 1 组 | D14: 虚构
A15: 店铺 | B15: 雾林茶舍 | C15: 第 1 组 | D15: 虚构
... A35: 公共热线 | B35: 12301、12345 | C35: 多个组 | D35: 真实的公共服务热线，剧本中只作为投诉渠道提到
